<?xml version="1.0"?>
<robot name="robot_arm">

  <!-- Base Link -->
  <link name="base_link"/>

  <!-- Link 1 -->
  <link name="link_1"/>
  
  <!-- Joint 1: Revolute Z-axis -->
  <joint name="joint_1" type="revolute">
    <parent link="base_link"/>
    <child link="link_1"/>
    <origin xyz="0 0 0" rpy="0 0 0"/>
    <axis xyz="0 0 1"/>
    <limit lower="-2.0944" upper="2.0944" effort="100" velocity="1.0"/>
  </joint>

  <!-- Link 2 -->
  <link name="link_2"/>

  <!-- Joint 2: Revolute x-axis -->
  <joint name="joint_2" type="revolute">
    <parent link="link_1"/>
    <child link="link_2"/>
    <origin xyz="0 0 0.037" rpy="0 0 0"/>
    <axis xyz="1 0 0"/>
    <limit lower="-0.9599" upper="1.5708" effort="100" velocity="1.0"/>
  </joint>

  <!-- Link 3 -->
  <link name="link_3"/>

  <!-- Joint 3: Revolute x-axis -->
  <joint name="joint_3" type="revolute">
    <parent link="link_2"/>
    <child link="link_3"/>
    <origin xyz="0 0 0.13" rpy="0 0 0"/>
    <axis xyz="1 0 0"/>
    <limit lower="-0.8727" upper="2.094" effort="100" velocity="1.0"/>
  </joint>

  <!-- Link 4 -->
  <link name="link_4"/>

  <!-- Joint 4: Revolute x-axis -->
  <joint name="joint_4" type="revolute">
    <parent link="link_3"/>
    <child link="link_4"/>
    <origin xyz="0 0 0.13" rpy="0 0 0"/>
    <axis xyz="1 0 0"/>
    <limit lower="-2.0071" upper="1.9199" effort="100" velocity="1.0"/>
  </joint>

  <!-- Link 5 -->
  <link name="link_5"/>

  <!-- Joint 5: Revolute Z-axis -->
  <joint name="joint_5" type="revolute">
    <parent link="link_4"/>
    <child link="link_5"/>
    <origin xyz="0 0 0.054" rpy="0 0 0"/>
    <axis xyz="0 0 1"/>
    <limit lower="-1.5708" upper="1.5708" effort="100" velocity="1.0"/>
  </joint>

  <!-- End Effector -->
  <link name="end_effector"/>

  <!-- Joint End Effector: Fixed -->
  <joint name="joint_6" type="fixed">
    <parent link="link_5"/>
    <child link="end_effector"/>
    <origin xyz="0 0 0.07" rpy="0 0 0"/>
  </joint>

</robot>
